Workbook

Sheet 說明
A1: 2026 日檢弱點分析 評語清單 N1～N5（模組整合版）
A3: 一、組裝順序
A4: 開頭句（表A）→ 言語知識評語（表B，N4/N5 含讀解）→ 讀解評語（表R，僅 N1～N3）→ 聽解評語（表C）→ 結尾句（表A）
A5: 學生看到的是一段連續文字，五個部分直接串接。
A7: 二、查表鍵
A8: 「評語清單」E 欄 = 級數|表|區間代碼|參考情報，例：N5|B_言語知識|中|BA。用 INDEX/MATCH 或 VLOOKUP 對 E 欄查即可。
A9: 表A 與表C、表R 的參考情報欄固定填「-」。
A11: 三、區間代碼
A12: 表A（總判定，看總分與及格線的差距）：單科未達／差20+／差1-19／過0-14／過15-39／過40+
A13: 「單科未達」的判斷優先：總分已達及格分，但任一科低於該科門檻 → 用此列。總分未達及格分時，一律依差距分列，不論單科。
A14: 表B／表R／表C（看各科分數與門檻）：未達（<門檻）／偏低／中／高，各段上限見「級別設定」。
A16: 四、參考情報代碼（僅表B 使用）
... A27: 「試算」分頁黃色欄位可直接輸入一位學生的成績，下方公式會自動判斷代碼並組出完整評語，可用來驗證邏輯，或直接把公式搬到你的系統設定。

Sheet 級別設定
A1: 級數 | B1: 及格分 | C1: 下一級 | D1: 言語知識科目名 | E1: 言語知識滿分 | F1: 言語知識門檻 | G1: 言語知識偏低上限 | H1: 言語知識中上限 | I1: 讀解滿分 | J1: 讀解門檻 | K1: 讀解偏低上限 | L1: 讀解中上限 | M1: 聽解滿分 | N1: 聽解門檻 | O1: 聽解偏低上限 | P1: 聽解中上限
A2: N1 | B2: 100 | C2: — | D2: 言語知識 | E2: 60 | F2: 19 | G2: 29 | H2: 44 | I2: 60 | J2: 19 | K2: 29 | L2: 44 | M2: 60 | N2: 19 | O2: 29 | P2: 44
A3: N2 | B3: 90 | C3: N1 | D3: 言語知識 | E3: 60 | F3: 19 | G3: 29 | H3: 44 | I3: 60 | J3: 19 | K3: 29 | L3: 44 | M3: 60 | N3: 19 | O3: 29 | P3: 44
A4: N3 | B4: 95 | C4: N2 | D4: 言語知識 | E4: 60 | F4: 19 | G4: 29 | H4: 44 | I4: 60 | J4: 19 | K4: 29 | L4: 44 | M4: 60 | N4: 19 | O4: 29 | P4: 44
A5: N4 | B5: 90 | C5: N3 | D5: 言語知識・讀解 | E5: 120 | F5: 38 | G5: 59 | H5: 89 | I5: 0 | J5: 0 | K5: 0 | L5: 0 | M5: 60 | N5: 19 | O5: 29 | P5: 44
A6: N5 | B6: 80 | C6: N4 | D6: 言語知識・讀解 | E6: 120 | F6: 38 | G6: 59 | H6: 89 | I6: 0 | J6: 0 | K6: 0 | L6: 0 | M6: 60 | N6: 19 | O6: 29 | P6: 44
A8: 註：及格分、滿分、門檻為 JLPT 官方規定；偏低上限與中上限為本表設計值（藍字可改）。讀解滿分 0 表示該級無獨立讀解科（N4／N5 併入言語知識）。

Sheet 評語清單
A1: 級數 | B1: 表 | C1: 區間代碼 | D1: 參考情報 | E1: 查表鍵 | F1: 條件說明 | G1: 分數下限 | H1: 分數上限 | I1: 評語／開頭句 | J1: 結尾句（表A） | K1: 備註
A2: N1 | B2: A_總判定 | C2: 單科未達 | D2: - | E2: N1|A_總判定|單科未達|- | F2: 總分≥100 但有一科未達門檻 | G2: 100 | H2: 180 | I2: 這次總分其實已經到了，只是有一科差了一點沒過線，真的很可惜。日檢是每一科都要過最低分數才算合格，所以這次還差一步，但你整體的實力其實已經夠了。 | J2: 現在先集中把那一科補起來，其他科維持住，12 月再考一次 N1，應該就能順利過了。 | K2: 總分達及格但任一科未達門檻，優先於其他列
A3: N1 | B3: A_總判定 | C3: 差20+ | D3: - | E3: N1|A_總判定|差20+|- | F3: 總分 ≤ 80（差 20 分以上） | G3: 0 | H3: 80 | I3: 你願意把成績交出來，這一步就很值得肯定。這次的分數離及格還有一段距離，表示 N1 的內容對現在的你來說還有點深，這很正常。 | J3: 12 月要再考一次 N1，還是先回 N2 拿一個穩穩的合格，可以找我聊聊再決定，兩種都可以。
A4: N1 | B4: A_總判定 | C4: 差1-19 | D4: - | E4: N1|A_總判定|差1-19|- | F4: 總分 81～99（差 1～19 分） | G4: 81 | H4: 99 | I4: 這次其實只差一點點就及格了，代表你 N1 的基礎已經有了，只是還不太穩。 | J4: 這種差距通常再練一輪就跨得過去，照上面的方向補一補，12 月再考一次 N1，不用太擔心。
A5: N1 | B5: A_總判定 | C5: 過0-14 | D5: - | E5: N1|A_總判定|過0-14|- | F5: 總分 100～114（合格，多 0～14 分） | G5: 100 | H5: 114 | I5: 恭喜合格囉！不過分數就在及格線附近，表示有些地方可能還不夠穩。 | J5: 12 月可以再考一次 N1 把分數拉高，證書上的分數之後申請或求職會有差；覺得夠用了的話，也可以先休息一下，把重心放在實際運用上。
A6: N1 | B6: A_總判定 | C6: 過15-39 | D6: - | E6: N1|A_總判定|過15-39|- | F6: 總分 115～139（合格，多 15～39 分） | G6: 115 | H6: 139 | I6: 恭喜合格！而且是穩穩地過，N1 的內容已經掌握得不錯了。 | J6: 12 月不一定要再考，想拚更高的分數可以再報一次；不然接下來就是把日文真正用起來，像是看原文書、聽日文的節目，或準備 BJT 商務日語。
A7: N1 | B7: A_總判定 | C7: 過40+ | D7: - | E7: N1|A_總判定|過40+|- | F7: 總分 ≥ 140（合格，多 40 分以上） | G7: 140 | H7: 180 | I7: 恭喜，這次的成績很不錯，N1 這關已經穩穩過了。 | J7: N1 已經不需要再考了，接下來可以把目標放在真正使用日文，像是留學、工作或翻譯的方向，需要的話我們可以聊聊下一步。
A8: N1 | B8: B_言語知識 | C8: 未達 | D8: AA | E8: N1|B_言語知識|未達|AA | F8: 言語知識 0～18／單字 A／文法 A | G8: 0 | H8: 18 | I8: 言語知識這科的分數比較低，還沒過線，不過單字和文法看起來都掌握得不錯，這和分數有點對不起來，可能是考試當天狀況不太好。建議先確認一下成績單，再做幾回模擬題看看實際落在哪裡。 | K8: 少見
A9: N1 | B9: B_言語知識 | C9: 未達 | D9: AB | E9: N1|B_言語知識|未達|AB | F9: 言語知識 0～18／單字 A／文法 B | G9: 0 | H9: 18 | I9: 言語知識這科的分數比較低，還沒過線，單字的部分你掌握得不錯，文法比較弱一些，N1 的文語表現和高階句型平常很少用到，容易一看就陌生。建議可以把 N1 的句型按意思分組整理，特別是書面才會出現的用法，多看例句記住語感，句型看熟了，這科的分數會慢慢回來。
A10: N1 | B10: B_言語知識 | C10: 未達 | D10: BA | E10: N1|B_言語知識|未達|BA | F10: 言語知識 0～18／單字 B／文法 A | G10: 0 | H10: 18 | I10: 言語知識這科的分數比較低，還沒過線，文法的部分掌握得還可以，單字比較弱一些，N1 的抽象詞彙和書面語量很大，平常比較少接觸。建議可以每天固定背一小批，從新聞和社論裡挑常出現的字先記，字認得多了，這科的分數會慢慢回來。
A11: N1 | B11: B_言語知識 | C11: 未達 | D11: BB | E11: N1|B_言語知識|未達|BB | F11: 言語知識 0～18／單字 B／文法 B | G11: 0 | H11: 18 | I11: 言語知識這科的分數比較低，還沒過線，表示你對N1 的單字和句型都還沒那麼熟練。建議先把N1 的單字和句型完整複習一輪，再做題目，分數會慢慢回來。
A12: N1 | B12: B_言語知識 | C12: 未達 | D12: C1 | E12: N1|B_言語知識|未達|C1 | F12: 言語知識 0～18／單項 C（另一項 A 或 B） | G12: 0 | H12: 18 | I12: 言語知識這科的分數比較低，還沒過線，〇〇這塊明顯還不太熟，分數主要是被這裡拉下來的。建議先不要急著做題目，回到課本把 N1 的〇〇確實學過一遍，會是比較實在的做法。
A13: N1 | B13: B_言語知識 | C13: 未達 | D13: CC | E13: N1|B_言語知識|未達|CC | F13: 言語知識 0～18／兩項都 C | G13: 0 | H13: 18 | I13: 言語知識這科的分數比較低，還沒過線，單字和文法都還沒那麼熟，表示N1 的內容對現在的你來說還太深，可能 N2 的部分也還沒完全穩。建議先回到課本從頭把內容確實學一遍，不用急著做題目，慢慢把底打穩。
A14: N1 | B14: B_言語知識 | C14: 偏低 | D14: AA | E14: N1|B_言語知識|偏低|AA | F14: 言語知識 19～29／單字 A／文法 A | G14: 19 | H14: 29 | I14: 言語知識有過線了，但分數還偏低，單字和文法看起來都掌握得不錯，可能是這次剛好考到不熟的範圍，或者作答的時候時間沒抓好。多做幾回計時的練習，把速度和穩定度一起拉上來就好。 | K14: 少見
A15: N1 | B15: B_言語知識 | C15: 偏低 | D15: AB | E15: N1|B_言語知識|偏低|AB | F15: 言語知識 19～29／單字 A／文法 B | G15: 19 | H15: 29 | I15: 言語知識有過線了，但分數還偏低，單字的部分掌握得不錯，文法還有些地方不太穩，像是意思相近的句型就容易選錯。建議把常錯的句型兩兩對照整理，弄清楚差在哪裡，會比單純背文法表來得有感。
A16: N1 | B16: B_言語知識 | C16: 偏低 | D16: BA | E16: N1|B_言語知識|偏低|BA | F16: 言語知識 19～29／單字 B／文法 A | G16: 19 | H16: 29 | I16: 言語知識有過線了，但分數還偏低，文法掌握得不錯，單字還有些地方不太穩，句型看得懂但字認不出來。建議可以每天固定背一小批，從新聞和社論裡挑常出現的字先記，不要只記中文意思，會比較記得住。
A17: N1 | B17: B_言語知識 | C17: 偏低 | D17: BB | E17: N1|B_言語知識|偏低|BB | F17: 言語知識 19～29／單字 B／文法 B | G17: 19 | H17: 29 | I17: 言語知識有過線了，但分數還偏低，代表你有一些基礎了，文法和單字都有一定掌握，但都還不夠熟，可能是練習量還不太夠。建議先把 N1 的教材完整複習一輪，再開始做題，幫助細節穩下來。
A18: N1 | B18: B_言語知識 | C18: 偏低 | D18: C1 | E18: N1|B_言語知識|偏低|C1 | F18: 言語知識 19～29／單項 C（另一項 A 或 B） | G18: 19 | H18: 29 | I18: 言語知識有過線了，但〇〇這塊明顯還不太熟，分數主要是被這裡拉下來的。建議先集中把 N1 的〇〇補起來，這科的分數會有感地往上。
A19: N1 | B19: B_言語知識 | C19: 偏低 | D19: CC | E19: N1|B_言語知識|偏低|CC | F19: 言語知識 19～29／兩項都 C | G19: 19 | H19: 29 | I19: 言語知識有過線了，但分數還偏低，單字和文法都還不太熟，這種情況比較少見，可能是考試當天狀況特別不好。建議先回到課本把 N1 的單字和文法確實補一輪，再做幾回模擬題確認狀況。
A20: N1 | B20: B_言語知識 | C20: 中 | D20: AA | E20: N1|B_言語知識|中|AA | F20: 言語知識 30～44／單字 A／文法 A | G20: 30 | H20: 44 | I20: 言語知識這次表現蠻穩定的，單字和文法都掌握得不錯，基礎應該已經打得很穩。接下來可以多接觸真實的日文素材，像是新聞、書籍或專業領域的文章，讓語彙和句型在實際使用裡更熟。
A21: N1 | B21: B_言語知識 | C21: 中 | D21: AB | E21: N1|B_言語知識|中|AB | F21: 言語知識 30～44／單字 A／文法 B | G21: 30 | H21: 44 | I21: 言語知識這次表現蠻穩定的，單字沒什麼問題，文法還可以再練練。可以把常錯的句型整理起來再練一輪，同時多讀書面的日文，讓高階句型在實際文章裡看熟。
A22: N1 | B22: B_言語知識 | C22: 中 | D22: BA | E22: N1|B_言語知識|中|BA | F22: 言語知識 30～44／單字 B／文法 A | G22: 30 | H22: 44 | I22: 言語知識這次表現蠻穩定的，文法沒什麼問題，單字還可以再多累積一些。可以趁這段時間多讀新聞和社論，把常出現的抽象詞彙和書面語慢慢累積起來。
A23: N1 | B23: B_言語知識 | C23: 中 | D23: BB | E23: N1|B_言語知識|中|BB | F23: 言語知識 30～44／單字 B／文法 B | G23: 30 | H23: 44 | I23: 言語知識這次表現蠻穩定的，不過單字和文法都還可以再練深一點，分數應該是靠整體語感撐起來的。建議把 N1 的基礎再過一輪，細節扎實了會更穩。
A24: N1 | B24: B_言語知識 | C24: 中 | D24: C1 | E24: N1|B_言語知識|中|C1 | F24: 言語知識 30～44／單項 C（另一項 A 或 B） | G24: 30 | H24: 44 | I24: 言語知識整體表現不錯，不過〇〇這塊有點意外地弱，可能是這次剛好考到不熟的範圍。順手把〇〇補一補就好，不用太擔心。
A25: N1 | B25: B_言語知識 | C25: 中 | D25: CC | E25: N1|B_言語知識|中|CC | F25: 言語知識 30～44／兩項都 C | G25: 30 | H25: 44 | I25: 言語知識整體分數不錯，不過單字和文法都還不太熟，這種情況比較少見。把單字和文法再補一輪，這科會更穩。 | K25: 少見
A26: N1 | B26: B_言語知識 | C26: 高 | D26: AA | E26: N1|B_言語知識|高|AA | F26: 言語知識 45～60／單字 A／文法 A | G26: 45 | H26: 60 | I26: 言語知識這次表現很好，單字和文法都已經是你的強項了。這科不太需要再針對考試練習，接下來就是在真實的日文裡持續使用，讓它一直保持在這個狀態。
A27: N1 | B27: B_言語知識 | C27: 高 | D27: AB | E27: N1|B_言語知識|高|AB | F27: 言語知識 45～60／單字 A／文法 B | G27: 45 | H27: 60 | I27: 言語知識這次表現很好，文法雖然還可以再更熟一點，但整體已經很穩了。想再拉高分數的話，可以把 N1 的文語表現再整理一輪；不然這科已經夠用了。
A28: N1 | B28: B_言語知識 | C28: 高 | D28: BA | E28: N1|B_言語知識|高|BA | F28: 言語知識 45～60／單字 B／文法 A | G28: 45 | H28: 60 | I28: 言語知識這次表現很好，單字雖然還可以再多累積，但整體已經很穩了。想再拉高分數的話，可以多累積書面語和抽象詞彙；不然這科已經夠用了。
A29: N1 | B29: B_言語知識 | C29: 高 | D29: 其他 | E29: N1|B_言語知識|高|其他 | F29: 言語知識 45～60／高段其他組合（備用） | G29: 45 | H29: 60 | I29: 言語知識分數很好，不過單字或文法有一項看起來還不太穩，可能是這次剛好考到不熟的範圍，順手補一下就好。 | K29: 少見
A30: N1 | B30: R_讀解 | C30: 未達 | D30: - | E30: N1|R_讀解|未達|- | F30: 讀解 0～18 | G30: 0 | H30: 18 | I30: 讀解這科的分數比較低，還沒過線，可能是 N1 的文章話題抽象、句子也長，字都看得懂但整段的意思抓不到，或者時間根本不夠。建議可以固定讀日文的社論或評論，每篇讀完用一兩句話整理作者的主張，練久了對這種文章的感覺會慢慢出來。
A31: N1 | B31: R_讀解 | C31: 偏低 | D31: - | E31: N1|R_讀解|偏低|- | F31: 讀解 19～29 | G31: 19 | H31: 29 | I31: 讀解有過線了，但分數還偏低，可能是抽象文章的邏輯跟不上，或者時間分配還不太順。建議練習的時候計時，先掃過題目再讀，遇到卡住的段落先跳過，把能拿的分先拿到。
A32: N1 | B32: R_讀解 | C32: 中 | D32: - | E32: N1|R_讀解|中|- | F32: 讀解 30～44 | G32: 30 | H32: 44 | I32: 讀解這次表現蠻穩定的，N1 的文章大部分都能讀懂了。接下來可以把閱讀變成日常，像是固定讀日文的書或專欄，這科會越來越穩的。
A33: N1 | B33: R_讀解 | C33: 高 | D33: - | E33: N1|R_讀解|高|- | F33: 讀解 45～60 | G33: 45 | H33: 60 | I33: 讀解這次表現很好，N1 的文章已經難不倒你了。接下來可以讀自己專業領域的日文資料，或直接讀原文書，實力已經足夠了。
A34: N1 | B34: C_聽解 | C34: 未達 | D34: - | E34: N1|C_聽解|未達|- | F34: 聽解 0～18 | G34: 0 | H34: 18 | I34: 聽力的分數比較低，還沒過線，可能是 N1 的聽解語速快、話題抽象，還常有好幾個人在討論，資訊一多就跟不上，或者每個字都聽懂了卻抓不到整體的意思。建議可以先從新聞和訪談這類有結構的素材開始，聽完用日文整理重點，再對照文字稿。
A35: N1 | B35: C_聽解 | C35: 偏低 | D35: - | E35: N1|C_聽解|偏低|- | F35: 聽解 19～29 | G35: 19 | H35: 29 | I35: 你已經能聽懂不少內容了，是很好的開始！只是抽象的話題或多人討論的時候還是容易跟丟。建議多聽討論型的節目或演講，練習分辨誰在說什麼、立場是什麼，聽完試著用自己的話整理。
A36: N1 | B36: C_聽解 | C36: 中 | D36: - | E36: N1|C_聽解|中|- | F36: 聽解 30～44 | G36: 30 | H36: 44 | I36: 這次的聽力表現不錯，N1 的內容大部分都能掌握了。接下來可以把聽力當成日常的一部分，像是固定聽日文的 podcast 或新聞，讓耳朵一直保持在這個狀態。
A37: N1 | B37: C_聽解 | C37: 高 | D37: - | E37: N1|C_聽解|高|- | F37: 聽解 45～60 | G37: 45 | H37: 60 | I37: 聽力是你的強項，N1 的聽解已經難不倒你了。接下來就是把日文真正用起來，像是聽專業領域的內容，或直接跟日本人對話，實力已經足夠支撐這些了。
A38: N2 | B38: A_總判定 | C38: 單科未達 | D38: - | E38: N2|A_總判定|單科未達|- | F38: 總分≥90 但有一科未達門檻 | G38: 90 | H38: 180 | I38: 這次總分其實已經到了，只是有一科差了一點沒過線，真的很可惜。日檢是每一科都要過最低分數才算合格，所以這次還差一步，但你整體的實力其實已經夠了。 | J38: 現在先集中把那一科補起來，其他科維持住，12 月再考一次 N2，應該就能順利過了。 | K38: 總分達及格但任一科未達門檻，優先於其他列
A39: N2 | B39: A_總判定 | C39: 差20+ | D39: - | E39: N2|A_總判定|差20+|- | F39: 總分 ≤ 70（差 20 分以上） | G39: 0 | H39: 70 | I39: 你願意把成績交出來，這一步就很值得肯定。這次的分數離及格還有一段距離，表示 N2 的單字量和長文對你來說還有點吃力。 | J39: 12 月可以再考一次 N2；如果 N3 還沒考過，也可以先把 N3 穩穩拿下來，會比較踏實。
A40: N2 | B40: A_總判定 | C40: 差1-19 | D40: - | E40: N2|A_總判定|差1-19|- | F40: 總分 71～89（差 1～19 分） | G40: 71 | H40: 89 | I40: 這次其實只差一點點就及格了，代表你 N2 的基礎已經有了，只是還不太穩。 | J40: 這種差距通常再練一輪就跨得過去，照上面的方向補一補，12 月再考一次 N2，不用太擔心。
...

Sheet 試算
A1: 試算：黃色欄位輸入成績，下方自動組出評語（三個範例）
A3: 級數 | B3: N5 | C3: N2 | D3: N1
A4: 總分 | B4: 84 | C4: 105 | D4: 72
A5: 言語知識分數（N4/N5 為言語知識・讀解） | B5: 70 | C5: 40 | D5: 22
A6: 讀解分數（僅 N1～N3） | C6: 28 | D6: 30
A7: 聽解分數 | B7: 14 | C7: 37 | D7: 20
A8: 參考情報 文字・語彙（A/B/C） | B8: B | C8: A | D8: C
A9: 參考情報 文法（A/B/C） | B9: A | C9: B | D9: B
A11: 及格分 | B11: =INDEX(級別設定!$B$2:$B$6,MATCH(B$3,級別設定!$A$2:$A$6,0)) -> 80 | C11: =INDEX(級別設定!$B$2:$B$6,MATCH(C$3,級別設定!$A$2:$A$6,0)) -> 90 | D11: =INDEX(級別設定!$B$2:$B$6,MATCH(D$3,級別設定!$A$2:$A$6,0)) -> 100
A12: 有獨立讀解科 | B12: =INDEX(級別設定!$I$2:$I$6,MATCH(B$3,級別設定!$A$2:$A$6,0))>0 -> FALSE | C12: =INDEX(級別設定!$I$2:$I$6,MATCH(C$3,級別設定!$A$2:$A$6,0))>0 -> TRUE | D12: =INDEX(級別設定!$I$2:$I$6,MATCH(D$3,級別設定!$A$2:$A$6,0))>0 -> TRUE
A13: 總分差距 | B13: =B4-B11 -> 4 | C13: =C4-C11 -> 15 | D13: =D4-D11 -> -28
A14: 任一科未達門檻 | B14: =OR(B5<INDEX(級別設定!$F$2:$F$6,MATCH(B$3,級別設定!$A$2:$A$6,0)),AND(B12,N(B6)<INDEX(級別設定!$J$2:$J$6,MATCH(B$3,級別設定!$A$2:$A$6,0))),B7<INDEX(級別設定!$N$2:$N$6,MATCH(B$3,級別設定!$A$2:$A$6,0))) -> TRUE | C14: =OR(C5<INDEX(級別設定!$F$2:$F$6,MATCH(C$3,級別設定!$A$2:$A$6,0)),AND(C12,N(C6)<INDEX(級別設定!$J$2:$J$6,MATCH(C$3,級別設定!$A$2:$A$6,0))),C7<INDEX(級別設定!$N$2:$N$6,MATCH(C$3,級別設定!$A$2:$A$6,0))) -> FALSE | D14: =OR(D5<INDEX(級別設定!$F$2:$F$6,MATCH(D$3,級別設定!$A$2:$A$6,0)),AND(D12,N(D6)<INDEX(級別設定!$J$2:$J$6,MATCH(D$3,級別設定!$A$2:$A$6,0))),D7<INDEX(級別設定!$N$2:$N$6,MATCH(D$3,級別設定!$A$2:$A$6,0))) -> FALSE
A15: 總判定代碼 | B15: =IF(AND(B13>=0,B14),"單科未達",_xlfn.IFS(B13<=-20,"差20+",B13<0,"差1-19",B13<15,"過0-14",B13<40,"過15-39",TRUE(),"過40+")) -> 單科未達 | C15: =IF(AND(C13>=0,C14),"單科未達",_xlfn.IFS(C13<=-20,"差20+",C13<0,"差1-19",C13<15,"過0-14",C13<40,"過15-39",TRUE(),"過40+")) -> 過15-39 | D15: =IF(AND(D13>=0,D14),"單科未達",_xlfn.IFS(D13<=-20,"差20+",D13<0,"差1-19",D13<15,"過0-14",D13<40,"過15-39",TRUE(),"過40+")) -> 差20+
A16: 言語知識區間 | B16: =_xlfn.IFS(B5<INDEX(級別設定!$F$2:$F$6,MATCH(B$3,級別設定!$A$2:$A$6,0)),"未達",B5<=INDEX(級別設定!$G$2:$G$6,MATCH(B$3,級別設定!$A$2:$A$6,0)),"偏低",B5<=INDEX(級別設定!$H$2:$H$6,MATCH(B$3,級別設定!$A$2:$A$6,0)),"中",TRUE(),"高") -> 中 | C16: =_xlfn.IFS(C5<INDEX(級別設定!$F$2:$F$6,MATCH(C$3,級別設定!$A$2:$A$6,0)),"未達",C5<=INDEX(級別設定!$G$2:$G$6,MATCH(C$3,級別設定!$A$2:$A$6,0)),"偏低",C5<=INDEX(級別設定!$H$2:$H$6,MATCH(C$3,級別設定!$A$2:$A$6,0)),"中",TRUE(),"高") -> 中 | D16: =_xlfn.IFS(D5<INDEX(級別設定!$F$2:$F$6,MATCH(D$3,級別設定!$A$2:$A$6,0)),"未達",D5<=INDEX(級別設定!$G$2:$G$6,MATCH(D$3,級別設定!$A$2:$A$6,0)),"偏低",D5<=INDEX(級別設定!$H$2:$H$6,MATCH(D$3,級別設定!$A$2:$A$6,0)),"中",TRUE(),"高") -> 偏低
A17: 讀解區間 | B17: =IF(B12,_xlfn.IFS(B6<INDEX(級別設定!$J$2:$J$6,MATCH(B$3,級別設定!$A$2:$A$6,0)),"未達",B6<=INDEX(級別設定!$K$2:$K$6,MATCH(B$3,級別設定!$A$2:$A$6,0)),"偏低",B6<=INDEX(級別設定!$L$2:$L$6,MATCH(B$3,級別設定!$A$2:$A$6,0)),"中",TRUE(),"高"),"-") -> - | C17: =IF(C12,_xlfn.IFS(C6<INDEX(級別設定!$J$2:$J$6,MATCH(C$3,級別設定!$A$2:$A$6,0)),"未達",C6<=INDEX(級別設定!$K$2:$K$6,MATCH(C$3,級別設定!$A$2:$A$6,0)),"偏低",C6<=INDEX(級別設定!$L$2:$L$6,MATCH(C$3,級別設定!$A$2:$A$6,0)),"中",TRUE(),"高"),"-") -> 偏低 | D17: =IF(D12,_xlfn.IFS(D6<INDEX(級別設定!$J$2:$J$6,MATCH(D$3,級別設定!$A$2:$A$6,0)),"未達",D6<=INDEX(級別設定!$K$2:$K$6,MATCH(D$3,級別設定!$A$2:$A$6,0)),"偏低",D6<=INDEX(級別設定!$L$2:$L$6,MATCH(D$3,級別設定!$A$2:$A$6,0)),"中",TRUE(),"高"),"-") -> 中
A18: 聽解區間 | B18: =_xlfn.IFS(B7<INDEX(級別設定!$N$2:$N$6,MATCH(B$3,級別設定!$A$2:$A$6,0)),"未達",B7<=INDEX(級別設定!$O$2:$O$6,MATCH(B$3,級別設定!$A$2:$A$6,0)),"偏低",B7<=INDEX(級別設定!$P$2:$P$6,MATCH(B$3,級別設定!$A$2:$A$6,0)),"中",TRUE(),"高") -> 未達 | C18: =_xlfn.IFS(C7<INDEX(級別設定!$N$2:$N$6,MATCH(C$3,級別設定!$A$2:$A$6,0)),"未達",C7<=INDEX(級別設定!$O$2:$O$6,MATCH(C$3,級別設定!$A$2:$A$6,0)),"偏低",C7<=INDEX(級別設定!$P$2:$P$6,MATCH(C$3,級別設定!$A$2:$A$6,0)),"中",TRUE(),"高") -> 中 | D18: =_xlfn.IFS(D7<INDEX(級別設定!$N$2:$N$6,MATCH(D$3,級別設定!$A$2:$A$6,0)),"未達",D7<=INDEX(級別設定!$O$2:$O$6,MATCH(D$3,級別設定!$A$2:$A$6,0)),"偏低",D7<=INDEX(級別設定!$P$2:$P$6,MATCH(D$3,級別設定!$A$2:$A$6,0)),"中",TRUE(),"高") -> 偏低
A19: 參考情報組合 | B19: =IF(AND(B8="C",B9="C"),"CC",IF(OR(B8="C",B9="C"),"C1",B8&B9)) -> BA | C19: =IF(AND(C8="C",C9="C"),"CC",IF(OR(C8="C",C9="C"),"C1",C8&C9)) -> AB | D19: =IF(AND(D8="C",D9="C"),"CC",IF(OR(D8="C",D9="C"),"C1",D8&D9)) -> C1
A20: 參考情報代碼（查表用） | B20: =IF(B16="高",IF(OR(B19="AA",B19="AB",B19="BA"),B19,"其他"),B19) -> BA | C20: =IF(C16="高",IF(OR(C19="AA",C19="AB",C19="BA"),C19,"其他"),C19) -> AB | D20: =IF(D16="高",IF(OR(D19="AA",D19="AB",D19="BA"),D19,"其他"),D19) -> C1
A21: 〇〇代入 | B21: =IF(B8="C","單字","文法") -> 文法 | C21: =IF(C8="C","單字","文法") -> 文法 | D21: =IF(D8="C","單字","文法") -> 單字
A23: 鍵 A | B23: =B3&"|A_總判定|"&B15&"|-" -> N5|A_總判定|單科未達|- | C23: =C3&"|A_總判定|"&C15&"|-" -> N2|A_總判定|過15-39|- | D23: =D3&"|A_總判定|"&D15&"|-" -> N1|A_總判定|差20+|-
A24: 鍵 B | B24: =B3&"|B_言語知識|"&B16&"|"&B20 -> N5|B_言語知識|中|BA | C24: =C3&"|B_言語知識|"&C16&"|"&C20 -> N2|B_言語知識|中|AB | D24: =D3&"|B_言語知識|"&D16&"|"&D20 -> N1|B_言語知識|偏低|C1
A25: 鍵 R | B25: =IF(B12,B3&"|R_讀解|"&B17&"|-","") | C25: =IF(C12,C3&"|R_讀解|"&C17&"|-","") -> N2|R_讀解|偏低|- | D25: =IF(D12,D3&"|R_讀解|"&D17&"|-","") -> N1|R_讀解|中|-
A26: 鍵 C | B26: =B3&"|C_聽解|"&B18&"|-" -> N5|C_聽解|未達|- | C26: =C3&"|C_聽解|"&C18&"|-" -> N2|C_聽解|中|- | D26: =D3&"|C_聽解|"&D18&"|-" -> N1|C_聽解|偏低|-
A28: 開頭句 | B28: =INDEX(評語清單!$I$2:$I$173,MATCH(B23,評語清單!$E$2:$E$173,0)) -> 這次總分其實已經到了，只是有一科差了一點沒過線，真的很可惜。日檢是每一科都要過最低分數才算合格，所以這次還差一步，但你整體的實力其實已經夠了。 | C28: =INDEX(評語清單!$I$2:$I$173,MATCH(C23,評語清單!$E$2:$E$173,0)) -> 恭喜合格！而且是穩穩地過，N2 的內容已經掌握得不錯了。 | D28: =INDEX(評語清單!$I$2:$I$173,MATCH(D23,評語清單!$E$2:$E$173,0)) -> 你願意把成績交出來，這一步就很值得肯定。這次的分數離及格還有一段距離，表示 N1 的內容對現在的你來說還有點深，這很正常。
A29: 言語知識評語 | B29: =SUBSTITUTE(INDEX(評語清單!$I$2:$I$173,MATCH(B24,評語清單!$E$2:$E$173,0)),"〇〇",B21) -> 言語知識・讀解這次表現蠻穩定的，文法沒什麼問題，單字還可以再多累積一些。可以趁這段時間把單字量往上拉，搭配長一點的文章一起讀，N4 的單字會多很多，現在先累積會比較輕鬆。 | C29: =SUBSTITUTE(INDEX(評語清單!$I$2:$I$173,MATCH(C24,評語清單!$E$2:$E$173,0)),"〇〇",C21) -> 言語知識這次表現蠻穩定的，單字沒什麼問題，文法還可以再練練。可以把常錯的句型整理起來再練一輪，同時慢慢接觸 N1 的文法，往上會比較順。 | D29: =SUBSTITUTE(INDEX(評語清單!$I$2:$I$173,MATCH(D24,評語清單!$E$2:$E$173,0)),"〇〇",D21) -> 言語知識有過線了，但單字這塊明顯還不太熟，分數主要是被這裡拉下來的。建議先集中把 N1 的單字補起來，這科的分數會有感地往上。
A30: 讀解評語 | B30: =IF(B12,INDEX(評語清單!$I$2:$I$173,MATCH(B25,評語清單!$E$2:$E$173,0)),"") | C30: =IF(C12,INDEX(評語清單!$I$2:$I$173,MATCH(C25,評語清單!$E$2:$E$173,0)),"") -> 讀解有過線了，但分數還偏低，可能是長文讀得太慢，或者兩篇文章比較的題型不太好處理。建議固定練習長文，先抓段落結構再看細節，時間分配會好很多。 | D30: =IF(D12,INDEX(評語清單!$I$2:$I$173,MATCH(D25,評語清單!$E$2:$E$173,0)),"") -> 讀解這次表現蠻穩定的，N1 的文章大部分都能讀懂了。接下來可以把閱讀變成日常，像是固定讀日文的書或專欄，這科會越來越穩的。
A31: 聽解評語 | B31: =INDEX(評語清單!$I$2:$I$173,MATCH(B26,評語清單!$E$2:$E$173,0)) -> 聽力的分數比較低，還沒過線，可能是語速還不習慣，或者句型一下聽過去就忘了。建議可以先看懂內容，再搭配音檔反覆練習，讓耳朵慢慢熟起來。 | C31: =INDEX(評語清單!$I$2:$I$173,MATCH(C26,評語清單!$E$2:$E$173,0)) -> 這次的聽力表現不錯，N2 的內容大部分都能掌握了。可以開始接觸日文的新聞、演講或討論節目，練習在資訊多的時候還能抓住重點，慢慢往 N1 的聽力靠近。 | D31: =INDEX(評語清單!$I$2:$I$173,MATCH(D26,評語清單!$E$2:$E$173,0)) -> 你已經能聽懂不少內容了，是很好的開始！只是抽象的話題或多人討論的時候還是容易跟丟。建議多聽討論型的節目或演講，練習分辨誰在說什麼、立場是什麼，聽完試著用自己的話整理。
A32: 結尾句 | B32: =INDEX(評語清單!$J$2:$J$173,MATCH(B23,評語清單!$E$2:$E$173,0)) -> 現在先集中把那一科補起來，其他科維持住，12 月再考一次 N5，應該就能順利過了。 | C32: =INDEX(評語清單!$J$2:$J$173,MATCH(C23,評語清單!$E$2:$E$173,0)) -> 現在可以開始慢慢接觸 N1 的內容，12 月直接報 N1，時間剛剛好。 | D32: =INDEX(評語清單!$J$2:$J$173,MATCH(D23,評語清單!$E$2:$E$173,0)) -> 12 月要再考一次 N1，還是先回 N2 拿一個穩穩的合格，可以找我聊聊再決定，兩種都可以。
A34: 完整評語 | B34: =B28&B29&B30&B31&B32 -> 這次總分其實已經到了，只是有一科差了一點沒過線，真的很可惜。日檢是每一科都要過最低分數才算合格，所以這次還差一步，但你整體的實力其實已經夠了。言語知識・讀解這次表現蠻穩定的，文法沒什麼問題，單字還可以再多累積一些。可以趁這段時間把單字量往上拉，搭配長一點的文章一起讀，N4 的單字會多很多，現在先累積會比較輕鬆。聽力的分數比較低，還沒過線，可能是語速還不習慣，或者句型一下聽過去就忘了。建議可以先看懂內容，再搭配音檔反覆練習，讓耳朵慢慢熟起來。現在先集中把那一科補起來，其他科維持住，12 月再考一次 N5，應該就能順利過了。 | C34: =C28&C29&C30&C31&C32 -> 恭喜合格！而且是穩穩地過，N2 的內容已經掌握得不錯了。言語知識這次表現蠻穩定的，單字沒什麼問題，文法還可以再練練。可以把常錯的句型整理起來再練一輪，同時慢慢接觸 N1 的文法，往上會比較順。讀解有過線了，但分數還偏低，可能是長文讀得太慢，或者兩篇文章比較的題型不太好處理。建議固定練習長文，先抓段落結構再看細節，時間分配會好很多。這次的聽力表現不錯，N2 的內容大部分都能掌握了。可以開始接觸日文的新聞、演講或討論節目，練習在資訊多的時候還能抓住重點，慢慢往 N1 的聽力靠近。現在可以開始慢慢接觸 N1 的內容，12 月直接報 N1，時間剛剛好。 | D34: =D28&D29&D30&D31&D32 -> 你願意把成績交出來，這一步就很值得肯定。這次的分數離及格還有一段距離，表示 N1 的內容對現在的你來說還有點深，這很正常。言語知識有過線了，但單字這塊明顯還不太熟，分數主要是被這裡拉下來的。建議先集中把 N1 的單字補起來，這科的分數會有感地往上。讀解這次表現蠻穩定的，N1 的文章大部分都能讀懂了。接下來可以把閱讀變成日常，像是固定讀日文的書或專欄，這科會越來越穩的。你已經能聽懂不少內容了，是很好的開始！只是抽象的話題或多人討論的時候還是容易跟丟。建議多聽討論型的節目或演講，練習分辨誰在說什麼、立場是什麼，聽完試著用自己的話整理。12 月要再考一次 N1，還是先回 N2 拿一個穩穩的合格，可以找我聊聊再決定，兩種都可以。
A36: 說明：黃色為輸入格；B12 的讀解分數 N4/N5 留空即可。公式只用 INDEX/MATCH/IFS/SUBSTITUTE，可直接搬到 Google Sheets。
